Workbook

Sheet Project Guide
A1: 📚 COMPLETE PROJECT GUIDE — Market Research & Customer Segmentation Tool
A3: ▶ ABOUT THIS PROJECT
A4: Tool Name | C4: Market Research & Customer Segmentation Tool
A5: Purpose | C5: Analyze 120 customers across demographics, behavior & RFM signals to drive marketing strategy
A6: Industry | C6: Marketing Analytics, Business Intelligence, E-Commerce, Retail, FMCG
A7: Tools Required | C7: Microsoft Excel 2019 / Office 365 (for XLOOKUP and dynamic arrays)
A8: Skill Level | C8: Beginner to Intermediate — all formulas explained with logic
A9: Sheet Count | C9: 7 sheets: Raw Data, Cleaned Data, Segmentation Logic, KPI Summary, Pivot Analysis, Dashboard, Guide
A11: ▶ SHEET STRUCTURE & PURPOSE
A12: 1. Raw Data | C12: Original 120-row customer dataset with 18 columns. Auto-assigns segments via formula.
A13: 2. Cleaned Data | C13: Links to Raw Data + adds Age Group, Income Bracket, Recency Days, RFM Category
A14: 3. Segmentation Logic | C14: Full reference guide: RFM scoring, segment definitions, formula directory
A15: 4. KPI Summary | C15: 12 KPI cards + segment table + region table — all formula-driven
A16: 5. Pivot Analysis | C16: 5 pre-built analysis tables simulating pivot output across key dimensions
A17: 6. Dashboard | C17: Executive dashboard with 6 KPI cards, 4 charts, and 6 insight cards
A18: 7. Project Guide | C18: This sheet — complete how-to documentation
A20: ▶ KEY FORMULAS EXPLAINED
A21: IF(cond,t,f) | C21: Core segmentation logic — assigns segment based on conditions
A22: ifs(C1,V1,C2,V2,...) | C22: Assigns multiple segments cleanly without nested IFs
A23: COUNTIFS(range,crit) | C23: Count customers matching multiple conditions (e.g., region + segment)
A24: SUMIFS(sum,range,cr) | C24: Sum revenue for a specific segment or region
A25: AVERAGEIFS(avg,r,c) | C25: Average AOV or spending for a specific segment
A26: IFERROR(formula,0) | C26: Prevents #DIV/0! and #N/A errors in ratio calculations
A27: TODAY()-lastdate | C27: Calculates recency in days for RFM analysis
A28: xlookup(val,arr,ret) | C28: Modern lookup: find customer data by ID across sheets
A29: ColorScaleRule | C29: Conditional formatting: green=high spend, red=low spend on Total Spending
A30: FormulaRule | C30: Highlights entire row based on segment (Premium=gold, At Risk=red)
A32: ▶ HOW TO USE THIS FILE
A33: Step 1 | C33: Start at Raw Data — review the dataset and note the 18 columns
A34: Step 2 | C34: Column R (Customer Segment) auto-calculates from the IF formula — don't edit
A35: Step 3 | C35: Open Cleaned Data to see derived columns: Age Group, Income Bracket, Recency, RFM
A36: Step 4 | C36: Visit Segmentation Logic to understand the business rules behind each segment
A37: Step 5 | C37: Go to KPI Summary for all metrics — all are formula-driven from Raw Data
A38: Step 6 | C38: Pivot Analysis shows 5 breakdown views: Segment, Region, Category, Channel, Age
A39: Step 7 | C39: Dashboard is the final output — use it for presentations and GitHub screenshots
A40: Step 8 | C40: To add new customers: insert rows in Raw Data between rows 4-123, extend formulas
A41: Step 9 | C41: Take screenshot of Dashboard tab for GitHub README and LinkedIn post
A42: Step 10 | C42: Export as PDF (File → Export) for email-ready report delivery
A44: ▶ RESUME / GITHUB / LINKEDIN
A45: GitHub Repo Name | C45: market-research-customer-segmentation-excel
...

Sheet Pivot Analysis
A1: 🔄 Pivot Analysis | Pre-built Summary Tables (Simulated Pivot Output)
A3: 📊 PIVOT 1 — Customers & Revenue by Segment | F3: 📊 PIVOT 2 — Customers by Region × Segment
A4: Segment | B4: Count | C4: Revenue (₹) | D4: Revenue % | F4: Region | G4: Premium Customer | H4: Loyal Customer | I4: Bargain Seeker | J4: At Risk | K4: General Customer
A5: Premium Customer | B5: =COUNTIFS('Raw Data'!R4:R123,"Premium Customer") -> 5 | C5: =SUMIFS('Raw Data'!K4:K123,'Raw Data'!R4:R123,"Premium Customer") -> 696035.32 | D5: =IFERROR(C5/SUM(C5:C9),0) -> 0.098733127 | F5: North | G5: =COUNTIFS('Raw Data'!E4:E123,"North",'Raw Data'!R4:R123,"Premium Customer") -> 0 | H5: =COUNTIFS('Raw Data'!E4:E123,"North",'Raw Data'!R4:R123,"Loyal Customer") -> 21 | I5: =COUNTIFS('Raw Data'!E4:E123,"North",'Raw Data'!R4:R123,"Bargain Seeker") -> 2 | J5: =COUNTIFS('Raw Data'!E4:E123,"North",'Raw Data'!R4:R123,"At Risk") -> 2 | K5: =COUNTIFS('Raw Data'!E4:E123,"North",'Raw Data'!R4:R123,"General Customer") -> 14
A6: Loyal Customer | B6: =COUNTIFS('Raw Data'!R4:R123,"Loyal Customer") -> 51 | C6: =SUMIFS('Raw Data'!K4:K123,'Raw Data'!R4:R123,"Loyal Customer") -> 4819813.7 | D6: =IFERROR(C6/SUM(C5:C9),0) -> 0.68369416 | F6: South | G6: =COUNTIFS('Raw Data'!E4:E123,"South",'Raw Data'!R4:R123,"Premium Customer") -> 0 | H6: =COUNTIFS('Raw Data'!E4:E123,"South",'Raw Data'!R4:R123,"Loyal Customer") -> 13 | I6: =COUNTIFS('Raw Data'!E4:E123,"South",'Raw Data'!R4:R123,"Bargain Seeker") -> 0 | J6: =COUNTIFS('Raw Data'!E4:E123,"South",'Raw Data'!R4:R123,"At Risk") -> 5 | K6: =COUNTIFS('Raw Data'!E4:E123,"South",'Raw Data'!R4:R123,"General Customer") -> 14
A7: Bargain Seeker | B7: =COUNTIFS('Raw Data'!R4:R123,"Bargain Seeker") -> 5 | C7: =SUMIFS('Raw Data'!K4:K123,'Raw Data'!R4:R123,"Bargain Seeker") -> 43674.76 | D7: =IFERROR(C7/SUM(C5:C9),0) -> 0.0061952972 | F7: East | G7: =COUNTIFS('Raw Data'!E4:E123,"East",'Raw Data'!R4:R123,"Premium Customer") -> 1 | H7: =COUNTIFS('Raw Data'!E4:E123,"East",'Raw Data'!R4:R123,"Loyal Customer") -> 2 | I7: =COUNTIFS('Raw Data'!E4:E123,"East",'Raw Data'!R4:R123,"Bargain Seeker") -> 2 | J7: =COUNTIFS('Raw Data'!E4:E123,"East",'Raw Data'!R4:R123,"At Risk") -> 3 | K7: =COUNTIFS('Raw Data'!E4:E123,"East",'Raw Data'!R4:R123,"General Customer") -> 3
A8: At Risk | B8: =COUNTIFS('Raw Data'!R4:R123,"At Risk") -> 13 | C8: =SUMIFS('Raw Data'!K4:K123,'Raw Data'!R4:R123,"At Risk") -> 73530.25 | D8: =IFERROR(C8/SUM(C5:C9),0) -> 0.010430321 | F8: West | G8: =COUNTIFS('Raw Data'!E4:E123,"West",'Raw Data'!R4:R123,"Premium Customer") -> 4 | H8: =COUNTIFS('Raw Data'!E4:E123,"West",'Raw Data'!R4:R123,"Loyal Customer") -> 15 | I8: =COUNTIFS('Raw Data'!E4:E123,"West",'Raw Data'!R4:R123,"Bargain Seeker") -> 1 | J8: =COUNTIFS('Raw Data'!E4:E123,"West",'Raw Data'!R4:R123,"At Risk") -> 3 | K8: =COUNTIFS('Raw Data'!E4:E123,"West",'Raw Data'!R4:R123,"General Customer") -> 15
A9: General Customer | B9: =COUNTIFS('Raw Data'!R4:R123,"General Customer") -> 46 | C9: =SUMIFS('Raw Data'!K4:K123,'Raw Data'!R4:R123,"General Customer") -> 1416609.4 | D9: =IFERROR(C9/SUM(C5:C9),0) -> 0.2009471 | F9: All | G9: =COUNTIFS('Raw Data'!R4:R123,"Premium Customer") -> 5 | H9: =COUNTIFS('Raw Data'!R4:R123,"Loyal Customer") -> 51 | I9: =COUNTIFS('Raw Data'!R4:R123,"Bargain Seeker") -> 5 | J9: =COUNTIFS('Raw Data'!R4:R123,"At Risk") -> 13 | K9: =COUNTIFS('Raw Data'!R4:R123,"General Customer") -> 46
A10: TOTAL | B10: =SUM(B5:B9) -> 120 | C10: =SUM(C5:C9) -> 7049663.5 | D10: =SUM(D5:D9) -> 1
A13: 📊 PIVOT 3 — Product Category Preference | F13: 📊 PIVOT 4 — Channel × Customer Type Analysis
A14: Category | B14: Customers | C14: Avg Spend (₹) | D14: % Customers | F14: Channel | G14: Cust Type | H14: Count | I14: Revenue (₹) | J14: Avg AOV (₹)
A15: Electronics | B15: =COUNTIFS('Raw Data'!L4:L123,"Electronics") -> 13 | C15: =IFERROR(AVERAGEIFS('Raw Data'!K4:K123,'Raw Data'!L4:L123,"Electronics"),0) -> 62804.024 | D15: =IFERROR(COUNTIFS('Raw Data'!L4:L123,"Electronics")/COUNTA('Raw Data'!A4:A123),0) -> 0.10833333 | F15: Online | G15: New | H15: =COUNTIFS('Raw Data'!M4:M123,"Online",'Raw Data'!N4:N123,"New") -> 23 | I15: =SUMIFS('Raw Data'!K4:K123,'Raw Data'!M4:M123,"Online",'Raw Data'!N4:N123,"New") -> 1508209.4 | J15: =IFERROR(AVERAGEIFS('Raw Data'!J4:J123,'Raw Data'!M4:M123,"Online",'Raw Data'!N4:N123,"New"),0) -> 4014.0035
A16: Fashion | B16: =COUNTIFS('Raw Data'!L4:L123,"Fashion") -> 23 | C16: =IFERROR(AVERAGEIFS('Raw Data'!K4:K123,'Raw Data'!L4:L123,"Fashion"),0) -> 57566.244 | D16: =IFERROR(COUNTIFS('Raw Data'!L4:L123,"Fashion")/COUNTA('Raw Data'!A4:A123),0) -> 0.19166667 | F16: Online | G16: Returning | H16: =COUNTIFS('Raw Data'!M4:M123,"Online",'Raw Data'!N4:N123,"Returning") -> 40 | I16: =SUMIFS('Raw Data'!K4:K123,'Raw Data'!M4:M123,"Online",'Raw Data'!N4:N123,"Returning") -> 2472188.6 | J16: =IFERROR(AVERAGEIFS('Raw Data'!J4:J123,'Raw Data'!M4:M123,"Online",'Raw Data'!N4:N123,"Returning"),0) -> 4263.9605
A17: Grocery | B17: =COUNTIFS('Raw Data'!L4:L123,"Grocery") -> 14 | C17: =IFERROR(AVERAGEIFS('Raw Data'!K4:K123,'Raw Data'!L4:L123,"Grocery"),0) -> 67784.967 | D17: =IFERROR(COUNTIFS('Raw Data'!L4:L123,"Grocery")/COUNTA('Raw Data'!A4:A123),0) -> 0.11666667 | F17: Offline | G17: New | H17: =COUNTIFS('Raw Data'!M4:M123,"Offline",'Raw Data'!N4:N123,"New") -> 16 | I17: =SUMIFS('Raw Data'!K4:K123,'Raw Data'!M4:M123,"Offline",'Raw Data'!N4:N123,"New") -> 691752.72 | J17: =IFERROR(AVERAGEIFS('Raw Data'!J4:J123,'Raw Data'!M4:M123,"Offline",'Raw Data'!N4:N123,"New"),0) -> 3750.4175
A18: Home & Decor | B18: =COUNTIFS('Raw Data'!L4:L123,"Home & Decor") -> 19 | C18: =IFERROR(AVERAGEIFS('Raw Data'!K4:K123,'Raw Data'!L4:L123,"Home & Decor"),0) -> 55945.196 | D18: =IFERROR(COUNTIFS('Raw Data'!L4:L123,"Home & Decor")/COUNTA('Raw Data'!A4:A123),0) -> 0.15833333 | F18: Offline | G18: Returning | H18: =COUNTIFS('Raw Data'!M4:M123,"Offline",'Raw Data'!N4:N123,"Returning") -> 41 | I18: =SUMIFS('Raw Data'!K4:K123,'Raw Data'!M4:M123,"Offline",'Raw Data'!N4:N123,"Returning") -> 2377512.8 | J18: =IFERROR(AVERAGEIFS('Raw Data'!J4:J123,'Raw Data'!M4:M123,"Offline",'Raw Data'!N4:N123,"Returning"),0) -> 4103.1339
A19: Sports | B19: =COUNTIFS('Raw Data'!L4:L123,"Sports") -> 14 | C19: =IFERROR(AVERAGEIFS('Raw Data'!K4:K123,'Raw Data'!L4:L123,"Sports"),0) -> 54011.793 | D19: =IFERROR(COUNTIFS('Raw Data'!L4:L123,"Sports")/COUNTA('Raw Data'!A4:A123),0) -> 0.11666667
A20: Beauty | B20: =COUNTIFS('Raw Data'!L4:L123,"Beauty") -> 19 | C20: =IFERROR(AVERAGEIFS('Raw Data'!K4:K123,'Raw Data'!L4:L123,"Beauty"),0) -> 54464.351 | D20: =IFERROR(COUNTIFS('Raw Data'!L4:L123,"Beauty")/COUNTA('Raw Data'!A4:A123),0) -> 0.15833333
A21: Books | B21: =COUNTIFS('Raw Data'!L4:L123,"Books") -> 8 | C21: =IFERROR(AVERAGEIFS('Raw Data'!K4:K123,'Raw Data'!L4:L123,"Books"),0) -> 82211.152 | D21: =IFERROR(COUNTIFS('Raw Data'!L4:L123,"Books")/COUNTA('Raw Data'!A4:A123),0) -> 0.066666667
A22: Travel | B22: =COUNTIFS('Raw Data'!L4:L123,"Travel") -> 10 | C22: =IFERROR(AVERAGEIFS('Raw Data'!K4:K123,'Raw Data'!L4:L123,"Travel"),0) -> 44856.229 | D22: =IFERROR(COUNTIFS('Raw Data'!L4:L123,"Travel")/COUNTA('Raw Data'!A4:A123),0) -> 0.083333333
A26: 📊 PIVOT 5 — Age Group Performance
A27: Age Group | B27: Count | C27: Avg Spend (₹) | D27: Avg AOV (₹) | E27: Preferred Channel
A28: 18-24 | B28: =COUNTIFS('Raw Data'!B4:B123,">=18",'Raw Data'!B4:B123,"<=24") -> 17 | C28: =IFERROR(AVERAGEIFS('Raw Data'!K4:K123,'Raw Data'!B4:B123,">=18",'Raw Data'!B4:B123,"<=24"),0) -> 42539.876 | D28: =IFERROR(AVERAGEIFS('Raw Data'!J4:J123,'Raw Data'!B4:B123,">=18",'Raw Data'!B4:B123,"<=24"),0) -> 3618.8512 | E28: =IFERROR(IF(COUNTIFS('Raw Data'!M4:M123,"Online",'Raw Data'!B4:B123,">=18",'Raw Data'!B4:B123,"<=24")>COUNTIFS('Raw Data'!M4:M123,"Offline",'Raw Data'!B4:B123,">=18",'Raw Data'!B4:B123,"<=24"),"Online","Offline"),"N/A") -> Online
A29: 25-34 | B29: =COUNTIFS('Raw Data'!B4:B123,">=25",'Raw Data'!B4:B123,"<=34") -> 25 | C29: =IFERROR(AVERAGEIFS('Raw Data'!K4:K123,'Raw Data'!B4:B123,">=25",'Raw Data'!B4:B123,"<=34"),0) -> 59352.316 | D29: =IFERROR(AVERAGEIFS('Raw Data'!J4:J123,'Raw Data'!B4:B123,">=25",'Raw Data'!B4:B123,"<=34"),0) -> 4096.022 | E29: =IFERROR(IF(COUNTIFS('Raw Data'!M4:M123,"Online",'Raw Data'!B4:B123,">=25",'Raw Data'!B4:B123,"<=34")>COUNTIFS('Raw Data'!M4:M123,"Offline",'Raw Data'!B4:B123,">=25",'Raw Data'!B4:B123,"<=34"),"Online","Offline"),"N/A") -> Offline
A30: 35-44 | B30: =COUNTIFS('Raw Data'!B4:B123,">=35",'Raw Data'!B4:B123,"<=44") -> 30 | C30: =IFERROR(AVERAGEIFS('Raw Data'!K4:K123,'Raw Data'!B4:B123,">=35",'Raw Data'!B4:B123,"<=44"),0) -> 65138.035 | D30: =IFERROR(AVERAGEIFS('Raw Data'!J4:J123,'Raw Data'!B4:B123,">=35",'Raw Data'!B4:B123,"<=44"),0) -> 4491.1707 | E30: =IFERROR(IF(COUNTIFS('Raw Data'!M4:M123,"Online",'Raw Data'!B4:B123,">=35",'Raw Data'!B4:B123,"<=44")>COUNTIFS('Raw Data'!M4:M123,"Offline",'Raw Data'!B4:B123,">=35",'Raw Data'!B4:B123,"<=44"),"Online","Offline"),"N/A") -> Online
A31: 45-54 | B31: =COUNTIFS('Raw Data'!B4:B123,">=45",'Raw Data'!B4:B123,"<=54") -> 18 | C31: =IFERROR(AVERAGEIFS('Raw Data'!K4:K123,'Raw Data'!B4:B123,">=45",'Raw Data'!B4:B123,"<=54"),0) -> 65194.794 | D31: =IFERROR(AVERAGEIFS('Raw Data'!J4:J123,'Raw Data'!B4:B123,">=45",'Raw Data'!B4:B123,"<=54"),0) -> 4269.6528 | E31: =IFERROR(IF(COUNTIFS('Raw Data'!M4:M123,"Online",'Raw Data'!B4:B123,">=45",'Raw Data'!B4:B123,"<=54")>COUNTIFS('Raw Data'!M4:M123,"Offline",'Raw Data'!B4:B123,">=45",'Raw Data'!B4:B123,"<=54"),"Online","Offline"),"N/A") -> Online
A32: 55+ | B32: =COUNTIFS('Raw Data'!B4:B123,">=55",'Raw Data'!B4:B123,"<=99") -> 30 | C32: =IFERROR(AVERAGEIFS('Raw Data'!K4:K123,'Raw Data'!B4:B123,">=55",'Raw Data'!B4:B123,"<=99"),0) -> 57167.677 | D32: =IFERROR(AVERAGEIFS('Raw Data'!J4:J123,'Raw Data'!B4:B123,">=55",'Raw Data'!B4:B123,"<=99"),0) -> 3853.526 | E32: =IFERROR(IF(COUNTIFS('Raw Data'!M4:M123,"Online",'Raw Data'!B4:B123,">=55",'Raw Data'!B4:B123,"<=99")>COUNTIFS('Raw Data'!M4:M123,"Offline",'Raw Data'!B4:B123,">=55",'Raw Data'!B4:B123,"<=99"),"Online","Offline"),"N/A") -> Online

Sheet Segmentation Logic
A1: 🎯 Segmentation Logic & Scoring Framework
A3: SECTION 1 — RFM SCORING MODEL
A4: Dimension | B4: Column Used | C4: Formula Logic | D4: Score 5 (Best) | E4: Score 4 | F4: Score 3 | G4: Score 2 | H4: Score 1 (Worst)
A5: Recency (R) | B5: Last Purchase Date | C5: TODAY()-last_purchase | D5: < 30 days | E5: 31-60 days | F5: 61-90 days | G5: 91-180 days | H5: > 180 days
A6: Frequency (F) | B6: Purchase Frequency | C6: Count of purchases | D6: > 20 times | E6: 15-20 | F6: 10-14 | G6: 5-9 | H6: < 5 times
A7: Monetary (M) | B7: Total Spending | C7: sum of purchases | D7: > ₹1,00,000 | E7: ₹75K-1L | F7: ₹50K-75K | G7: ₹25K-50K | H7: < ₹25,000
A9: SECTION 2 — CUSTOMER SEGMENT DEFINITIONS & BUSINESS RULES
A10: Segment Name | B10: Color Code | C10: Total Spending | D10: Engagement | E10: Frequency | F10: Recency | G10: Discount Sens. | H10: Marketing Action
A11: Premium Customer | B11: Dark Blue / Gold | C11: ≥ ₹1,00,000 | D11: High | E11: Any | F11: Any | G11: Any | H11: VIP programs, exclusive offers
A12: Loyal Customer | B12: Green | C12: ≥ ₹50,000 | D12: Medium+ | E12: ≥ 12 | F12: < 90d | G12: Any | H12: Loyalty rewards, early access
A13: Bargain Seeker | B13: Orange | C13: < ₹30,000 | D13: Any | E13: ≥ 5 | F13: Any | G13: High | H13: Flash sales, bundle deals
A14: At Risk | B14: Red | C14: Any | D14: Low | E14: < 5 | F14: > 180d | G14: Any | H14: Win-back email, discount offer
A15: General Customer | B15: Light Blue | C15: Any | D15: Medium | E15: Any | F15: Any | G15: Medium | H15: Nurture campaigns, cross-sell
A17: SECTION 3 — KEY EXCEL FORMULAS USED IN THIS PROJECT
A18: Formula | B18: Purpose | C18: Example Used in Project | D18: Sheet | E18: Output Type
A19: IF(,TRUE()) | B19: Conditional logic | C19: IF(totalspend>=100000,"Premium","Other") | D19: Raw Data | E19: Text/Number
A20: ifs() | B20: Multiple conditions | C20: ifs(eng="High","Premium",freq>=12,"Loyal",...) | D20: Raw Data | E20: Text
A21: SUMIFS() | B21: Conditional sum | C21: SUMIFS(totalspend,segment,"Loyal") | D21: KPI Summary | E21: Number
A22: COUNTIFS() | B22: Conditional count | C22: COUNTIFS(region,"West",segment,"Premium") | D22: KPI Summary | E22: Number
A23: AVERAGEIFS() | B23: Conditional average | C23: AVERAGEIFS(aov,segment,"Loyal") | D23: KPI Summary | E23: Number
A24: IFERROR() | B24: Error handling | C24: IFERROR(VLOOKUP(...),"Not Found") | D24: Cleaned Data | E24: Any
A25: TODAY() | B25: Current date | C25: TODAY()-lastpurchasedate | D25: Cleaned Data | E25: Date/Number
A26: xlookup() | B26: Modern lookup | C26: xlookup(custid,custtable,segmentcol,"N/A") | D26: KPI Summary | E26: Any
A27: TEXT() | B27: Format as text | C27: TEXT(lastpurchasedate,"MMM-YYYY") | D27: Dashboard | E27: Text
A28: LARGE()/SMALL() | B28: Rank values | C28: LARGE(totalspend,1) for top spender | D28: KPI Summary | E28: Number

Sheet Cleaned Data
A1: ✅ Cleaned & Enriched Data | With Age Group, Income Bracket & RFM Indicators
A2: Customer ID | B2: Age | C2: Gender | D2: City | E2: Region | F2: Income Level | G2: Annual Income (₹) | H2: Occupation | I2: Purchase Frequency | J2: Avg Order Value (₹) | K2: Total Spending (₹) | L2: Preferred Category | M2: Purchase Channel | N2: Customer Type | O2: Engagement Level | P2: Discount Sensitivity | Q2: Last Purchase Date | R2: Customer Segment | S2: Age Group | T2: Income Bracket | U2: Recency (Days) | V2: RFM Category
A3: ='Raw Data'!A4 -> CUST0001 | B3: ='Raw Data'!B4 -> 26 | C3: ='Raw Data'!C4 -> Male | D3: ='Raw Data'!D4 -> Delhi | E3: ='Raw Data'!E4 -> North | F3: ='Raw Data'!F4 -> Low | G3: ='Raw Data'!G4 -> 22066 | H3: ='Raw Data'!H4 -> Self-Employed | ... R3: ='Raw Data'!R4 -> Loyal Customer | S3: =IF(B3<25,"18-24",IF(B3<35,"25-34",IF(B3<45,"35-44",IF(B3<55,"45-54","55+")))) -> 25-34 | T3: =IF(G3<25000,"Low (< ₹25K)",IF(G3<50000,"Mid (₹25K-50K)","High (> ₹50K)")) -> Low (< ₹25K) | U3: =IFERROR(TODAY()-Q3,"") -> 316 | V3: =IF(AND(U3<60,I3>=12,K3>=80000),"Champions",IF(AND(U3<90,I3>=8,K3>=40000),"Loyal",IF(AND(U3>180,I3<5),"At Risk / Churned",IF(AND(U3<120,I3>=6),"Potential Loyal","Needs Attention")))) -> Needs Attention
A4: ='Raw Data'!A5 -> CUST0002 | B4: ='Raw Data'!B5 -> 18 | C4: ='Raw Data'!C5 -> Male | D4: ='Raw Data'!D5 -> Hyderabad | E4: ='Raw Data'!E5 -> South | F4: ='Raw Data'!F5 -> Mid | G4: ='Raw Data'!G5 -> 30231 | H4: ='Raw Data'!H5 -> Freelancer | ... R4: ='Raw Data'!R5 -> General Customer | S4: =IF(B4<25,"18-24",IF(B4<35,"25-34",IF(B4<45,"35-44",IF(B4<55,"45-54","55+")))) -> 18-24 | T4: =IF(G4<25000,"Low (< ₹25K)",IF(G4<50000,"Mid (₹25K-50K)","High (> ₹50K)")) -> Mid (₹25K-50K) | U4: =IFERROR(TODAY()-Q4,"") -> 729 | V4: =IF(AND(U4<60,I4>=12,K4>=80000),"Champions",IF(AND(U4<90,I4>=8,K4>=40000),"Loyal",IF(AND(U4>180,I4<5),"At Risk / Churned",IF(AND(U4<120,I4>=6),"Potential Loyal","Needs Attention")))) -> Needs Attention
A5: ='Raw Data'!A6 -> CUST0003 | B5: ='Raw Data'!B6 -> 64 | C5: ='Raw Data'!C6 -> Female | D5: ='Raw Data'!D6 -> Pune | E5: ='Raw Data'!E6 -> West | F5: ='Raw Data'!F6 -> High | G5: ='Raw Data'!G6 -> 66361 | H5: ='Raw Data'!H6 -> Self-Employed | ... R5: ='Raw Data'!R6 -> General Customer | S5: =IF(B5<25,"18-24",IF(B5<35,"25-34",IF(B5<45,"35-44",IF(B5<55,"45-54","55+")))) -> 55+ | T5: =IF(G5<25000,"Low (< ₹25K)",IF(G5<50000,"Mid (₹25K-50K)","High (> ₹50K)")) -> High (> ₹50K) | U5: =IFERROR(TODAY()-Q5,"") -> 463 | V5: =IF(AND(U5<60,I5>=12,K5>=80000),"Champions",IF(AND(U5<90,I5>=8,K5>=40000),"Loyal",IF(AND(U5>180,I5<5),"At Risk / Churned",IF(AND(U5<120,I5>=6),"Potential Loyal","Needs Attention")))) -> Needs Attention
A6: ='Raw Data'!A7 -> CUST0004 | B6: ='Raw Data'!B7 -> 24 | C6: ='Raw Data'!C7 -> Female | D6: ='Raw Data'!D7 -> Hyderabad | E6: ='Raw Data'!E7 -> South | F6: ='Raw Data'!F7 -> Mid | G6: ='Raw Data'!G7 -> 34108 | H6: ='Raw Data'!H7 -> Student | ... R6: ='Raw Data'!R7 -> Loyal Customer | S6: =IF(B6<25,"18-24",IF(B6<35,"25-34",IF(B6<45,"35-44",IF(B6<55,"45-54","55+")))) -> 18-24 | T6: =IF(G6<25000,"Low (< ₹25K)",IF(G6<50000,"Mid (₹25K-50K)","High (> ₹50K)")) -> Mid (₹25K-50K) | U6: =IFERROR(TODAY()-Q6,"") -> 147 | V6: =IF(AND(U6<60,I6>=12,K6>=80000),"Champions",IF(AND(U6<90,I6>=8,K6>=40000),"Loyal",IF(AND(U6>180,I6<5),"At Risk / Churned",IF(AND(U6<120,I6>=6),"Potential Loyal","Needs Attention")))) -> Needs Attention
A7: ='Raw Data'!A8 -> CUST0005 | B7: ='Raw Data'!B8 -> 42 | C7: ='Raw Data'!C8 -> Male | D7: ='Raw Data'!D8 -> Jaipur | E7: ='Raw Data'!E8 -> North | F7: ='Raw Data'!F8 -> High | G7: ='Raw Data'!G8 -> 78785 | H7: ='Raw Data'!H8 -> Salaried | ... R7: ='Raw Data'!R8 -> Loyal Customer | S7: =IF(B7<25,"18-24",IF(B7<35,"25-34",IF(B7<45,"35-44",IF(B7<55,"45-54","55+")))) -> 35-44 | T7: =IF(G7<25000,"Low (< ₹25K)",IF(G7<50000,"Mid (₹25K-50K)","High (> ₹50K)")) -> High (> ₹50K) | U7: =IFERROR(TODAY()-Q7,"") -> 801 | V7: =IF(AND(U7<60,I7>=12,K7>=80000),"Champions",IF(AND(U7<90,I7>=8,K7>=40000),"Loyal",IF(AND(U7>180,I7<5),"At Risk / Churned",IF(AND(U7<120,I7>=6),"Potential Loyal","Needs Attention")))) -> Needs Attention
A8: ='Raw Data'!A9 -> CUST0006 | B8: ='Raw Data'!B9 -> 38 | C8: ='Raw Data'!C9 -> Female | D8: ='Raw Data'!D9 -> Delhi | E8: ='Raw Data'!E9 -> North | F8: ='Raw Data'!F9 -> Low | G8: ='Raw Data'!G9 -> 13483 | H8: ='Raw Data'!H9 -> Freelancer | ... R8: ='Raw Data'!R9 -> Loyal Customer | S8: =IF(B8<25,"18-24",IF(B8<35,"25-34",IF(B8<45,"35-44",IF(B8<55,"45-54","55+")))) -> 35-44 | T8: =IF(G8<25000,"Low (< ₹25K)",IF(G8<50000,"Mid (₹25K-50K)","High (> ₹50K)")) -> Low (< ₹25K) | U8: =IFERROR(TODAY()-Q8,"") -> 691 | V8: =IF(AND(U8<60,I8>=12,K8>=80000),"Champions",IF(AND(U8<90,I8>=8,K8>=40000),"Loyal",IF(AND(U8>180,I8<5),"At Risk / Churned",IF(AND(U8<120,I8>=6),"Potential Loyal","Needs Attention")))) -> Needs Attention
A9: ='Raw Data'!A10 -> CUST0007 | B9: ='Raw Data'!B10 -> 26 | C9: ='Raw Data'!C10 -> Male | D9: ='Raw Data'!D10 -> Lucknow | E9: ='Raw Data'!E10 -> North | F9: ='Raw Data'!F10 -> Mid | G9: ='Raw Data'!G10 -> 41171 | H9: ='Raw Data'!H10 -> Self-Employed | ... R9: ='Raw Data'!R10 -> General Customer | S9: =IF(B9<25,"18-24",IF(B9<35,"25-34",IF(B9<45,"35-44",IF(B9<55,"45-54","55+")))) -> 25-34 | T9: =IF(G9<25000,"Low (< ₹25K)",IF(G9<50000,"Mid (₹25K-50K)","High (> ₹50K)")) -> Mid (₹25K-50K) | U9: =IFERROR(TODAY()-Q9,"") -> 137 | V9: =IF(AND(U9<60,I9>=12,K9>=80000),"Champions",IF(AND(U9<90,I9>=8,K9>=40000),"Loyal",IF(AND(U9>180,I9<5),"At Risk / Churned",IF(AND(U9<120,I9>=6),"Potential Loyal","Needs Attention")))) -> Needs Attention
A10: ='Raw Data'!A11 -> CUST0008 | B10: ='Raw Data'!B11 -> 53 | C10: ='Raw Data'!C11 -> Female | D10: ='Raw Data'!D11 -> Kolkata | E10: ='Raw Data'!E11 -> East | F10: ='Raw Data'!F11 -> High | G10: ='Raw Data'!G11 -> 65014 | H10: ='Raw Data'!H11 -> Business Owner | ... R10: ='Raw Data'!R11 -> Premium Customer | S10: =IF(B10<25,"18-24",IF(B10<35,"25-34",IF(B10<45,"35-44",IF(B10<55,"45-54","55+")))) -> 45-54 | T10: =IF(G10<25000,"Low (< ₹25K)",IF(G10<50000,"Mid (₹25K-50K)","High (> ₹50K)")) -> High (> ₹50K) | U10: =IFERROR(TODAY()-Q10,"") -> 485 | V10: =IF(AND(U10<60,I10>=12,K10>=80000),"Champions",IF(AND(U10<90,I10>=8,K10>=40000),"Loyal",IF(AND(U10>180,I10<5),"At Risk / Churned",IF(AND(U10<120,I10>=6),"Potential Loyal","Needs Attention")))) -> Needs Attention
A11: ='Raw Data'!A12 -> CUST0009 | B11: ='Raw Data'!B12 -> 29 | C11: ='Raw Data'!C12 -> Other | D11: ='Raw Data'!D12 -> Ahmedabad | E11: ='Raw Data'!E12 -> West | F11: ='Raw Data'!F12 -> Low | G11: ='Raw Data'!G12 -> 18317 | H11: ='Raw Data'!H12 -> Self-Employed | ... R11: ='Raw Data'!R12 -> Loyal Customer | S11: =IF(B11<25,"18-24",IF(B11<35,"25-34",IF(B11<45,"35-44",IF(B11<55,"45-54","55+")))) -> 25-34 | T11: =IF(G11<25000,"Low (< ₹25K)",IF(G11<50000,"Mid (₹25K-50K)","High (> ₹50K)")) -> Low (< ₹25K) | U11: =IFERROR(TODAY()-Q11,"") -> 668 | V11: =IF(AND(U11<60,I11>=12,K11>=80000),"Champions",IF(AND(U11<90,I11>=8,K11>=40000),"Loyal",IF(AND(U11>180,I11<5),"At Risk / Churned",IF(AND(U11<120,I11>=6),"Potential Loyal","Needs Attention")))) -> Needs Attention
A12: ='Raw Data'!A13 -> CUST0010 | B12: ='Raw Data'!B13 -> 37 | C12: ='Raw Data'!C13 -> Female | D12: ='Raw Data'!D13 -> Ahmedabad | E12: ='Raw Data'!E13 -> West | F12: ='Raw Data'!F13 -> Low | G12: ='Raw Data'!G13 -> 13923 | H12: ='Raw Data'!H13 -> Student | ... R12: ='Raw Data'!R13 -> Loyal Customer | S12: =IF(B12<25,"18-24",IF(B12<35,"25-34",IF(B12<45,"35-44",IF(B12<55,"45-54","55+")))) -> 35-44 | T12: =IF(G12<25000,"Low (< ₹25K)",IF(G12<50000,"Mid (₹25K-50K)","High (> ₹50K)")) -> Low (< ₹25K) | U12: =IFERROR(TODAY()-Q12,"") -> 763 | V12: =IF(AND(U12<60,I12>=12,K12>=80000),"Champions",IF(AND(U12<90,I12>=8,K12>=40000),"Loyal",IF(AND(U12>180,I12<5),"At Risk / Churned",IF(AND(U12<120,I12>=6),"Potential Loyal","Needs Attention")))) -> Needs Attention
A13: ='Raw Data'!A14 -> CUST0011 | B13: ='Raw Data'!B14 -> 56 | C13: ='Raw Data'!C14 -> Male | D13: ='Raw Data'!D14 -> Ahmedabad | E13: ='Raw Data'!E14 -> West | F13: ='Raw Data'!F14 -> High | G13: ='Raw Data'!G14 -> 76365 | H13: ='Raw Data'!H14 -> Salaried | ... R13: ='Raw Data'!R14 -> Loyal Customer | S13: =IF(B13<25,"18-24",IF(B13<35,"25-34",IF(B13<45,"35-44",IF(B13<55,"45-54","55+")))) -> 55+ | T13: =IF(G13<25000,"Low (< ₹25K)",IF(G13<50000,"Mid (₹25K-50K)","High (> ₹50K)")) -> High (> ₹50K) | U13: =IFERROR(TODAY()-Q13,"") -> 385 | V13: =IF(AND(U13<60,I13>=12,K13>=80000),"Champions",IF(AND(U13<90,I13>=8,K13>=40000),"Loyal",IF(AND(U13>180,I13<5),"At Risk / Churned",IF(AND(U13<120,I13>=6),"Potential Loyal","Needs Attention")))) -> Needs Attention
A14: ='Raw Data'!A15 -> CUST0012 | B14: ='Raw Data'!B15 -> 55 | C14: ='Raw Data'!C15 -> Male | D14: ='Raw Data'!D15 -> Hyderabad | E14: ='Raw Data'!E15 -> South | F14: ='Raw Data'!F15 -> Low | G14: ='Raw Data'!G15 -> 19075 | H14: ='Raw Data'!H15 -> Student | ... R14: ='Raw Data'!R15 -> At Risk | S14: =IF(B14<25,"18-24",IF(B14<35,"25-34",IF(B14<45,"35-44",IF(B14<55,"45-54","55+")))) -> 55+ | T14: =IF(G14<25000,"Low (< ₹25K)",IF(G14<50000,"Mid (₹25K-50K)","High (> ₹50K)")) -> Low (< ₹25K) | U14: =IFERROR(TODAY()-Q14,"") -> 801 | V14: =IF(AND(U14<60,I14>=12,K14>=80000),"Champions",IF(AND(U14<90,I14>=8,K14>=40000),"Loyal",IF(AND(U14>180,I14<5),"At Risk / Churned",IF(AND(U14<120,I14>=6),"Potential Loyal","Needs Attention")))) -> At Risk / Churned
... A122: ='Raw Data'!A123 -> CUST0120 | B122: ='Raw Data'!B123 -> 58 | C122: ='Raw Data'!C123 -> Male | D122: ='Raw Data'!D123 -> Hyderabad | E122: ='Raw Data'!E123 -> South | F122: ='Raw Data'!F123 -> High | G122: ='Raw Data'!G123 -> 119924 | H122: ='Raw Data'!H123 -> Freelancer | ... R122: ='Raw Data'!R123 -> At Risk | S122: =IF(B122<25,"18-24",IF(B122<35,"25-34",IF(B122<45,"35-44",IF(B122<55,"45-54","55+")))) -> 55+ | T122: =IF(G122<25000,"Low (< ₹25K)",IF(G122<50000,"Mid (₹25K-50K)","High (> ₹50K)")) -> High (> ₹50K) | U122: =IFERROR(TODAY()-Q122,"") -> 676 | V122: =IF(AND(U122<60,I122>=12,K122>=80000),"Champions",IF(AND(U122<90,I122>=8,K122>=40000),"Loyal",IF(AND(U122>180,I122<5),"At Risk / Churned",IF(AND(U122<120,I122>=6),"Potential Loyal","Needs Attention")))) -> At Risk / Churned

Sheet Raw Data
A1: 📊 Market Research & Customer Segmentation Tool | Raw Dataset | FY 2024-25
A2: Source: Internal CRM | Last Updated: Dec 2025 | Records: 120 Customers
A3: Customer ID | B3: Age | C3: Gender | D3: City | E3: Region | F3: Income Level | G3: Annual Income (₹) | H3: Occupation | I3: Purchase Frequency | J3: Avg Order Value (₹) | K3: Total Spending (₹) | L3: Preferred Category | M3: Purchase Channel | N3: Customer Type | O3: Engagement Level | P3: Discount Sensitivity | Q3: Last Purchase Date | R3: Customer Segment
A4: CUST0001 | B4: 26 | C4: Male | D4: Delhi | E4: North | F4: Low | G4: 22066 | H4: Self-Employed | I4: 19 | J4: 3548.8 | K4: 67427.2 | L4: Home & Decor | M4: Offline | N4: Returning | O4: Low | P4: Low | Q4: 45809 | R4: =IF(AND(K4>=100000,O4="High"),"Premium Customer",IF(AND(I4>=12,K4>=50000),"Loyal Customer",IF(AND(P4="High",J4<1500),"Bargain Seeker",IF(AND(TODAY()-Q4>180,I4<5),"At Risk","General Customer")))) -> Loyal Customer
A5: CUST0002 | B5: 18 | C5: Male | D5: Hyderabad | E5: South | F5: Mid | G5: 30231 | H5: Freelancer | I5: 11 | J5: 2439.61 | K5: 26835.71 | L5: Fashion | M5: Offline | N5: New | O5: Low | P5: High | Q5: 45396 | R5: =IF(AND(K5>=100000,O5="High"),"Premium Customer",IF(AND(I5>=12,K5>=50000),"Loyal Customer",IF(AND(P5="High",J5<1500),"Bargain Seeker",IF(AND(TODAY()-Q5>180,I5<5),"At Risk","General Customer")))) -> General Customer
A6: CUST0003 | B6: 64 | C6: Female | D6: Pune | E6: West | F6: High | G6: 66361 | H6: Self-Employed | I6: 13 | J6: 906.76 | K6: 11787.88 | L6: Fashion | M6: Online | N6: Returning | O6: Medium | P6: Medium | Q6: 45662 | R6: =IF(AND(K6>=100000,O6="High"),"Premium Customer",IF(AND(I6>=12,K6>=50000),"Loyal Customer",IF(AND(P6="High",J6<1500),"Bargain Seeker",IF(AND(TODAY()-Q6>180,I6<5),"At Risk","General Customer")))) -> General Customer
A7: CUST0004 | B7: 24 | C7: Female | D7: Hyderabad | E7: South | F7: Mid | G7: 34108 | H7: Student | I7: 21 | J7: 6722.65 | K7: 141175.65 | L7: Fashion | M7: Online | N7: New | O7: Low | P7: Medium | Q7: 45978 | R7: =IF(AND(K7>=100000,O7="High"),"Premium Customer",IF(AND(I7>=12,K7>=50000),"Loyal Customer",IF(AND(P7="High",J7<1500),"Bargain Seeker",IF(AND(TODAY()-Q7>180,I7<5),"At Risk","General Customer")))) -> Loyal Customer
A8: CUST0005 | B8: 42 | C8: Male | D8: Jaipur | E8: North | F8: High | G8: 78785 | H8: Salaried | I8: 22 | J8: 2796.98 | K8: 61533.56 | L8: Books | M8: Offline | N8: Returning | O8: High | P8: Low | Q8: 45324 | R8: =IF(AND(K8>=100000,O8="High"),"Premium Customer",IF(AND(I8>=12,K8>=50000),"Loyal Customer",IF(AND(P8="High",J8<1500),"Bargain Seeker",IF(AND(TODAY()-Q8>180,I8<5),"At Risk","General Customer")))) -> Loyal Customer
A9: CUST0006 | B9: 38 | C9: Female | D9: Delhi | E9: North | F9: Low | G9: 13483 | H9: Freelancer | I9: 13 | J9: 7112.06 | K9: 92456.78 | L9: Sports | M9: Offline | N9: New | O9: Medium | P9: Low | Q9: 45434 | R9: =IF(AND(K9>=100000,O9="High"),"Premium Customer",IF(AND(I9>=12,K9>=50000),"Loyal Customer",IF(AND(P9="High",J9<1500),"Bargain Seeker",IF(AND(TODAY()-Q9>180,I9<5),"At Risk","General Customer")))) -> Loyal Customer
A10: CUST0007 | B10: 26 | C10: Male | D10: Lucknow | E10: North | F10: Mid | G10: 41171 | H10: Self-Employed | I10: 2 | J10: 6930.49 | K10: 13860.98 | L10: Fashion | M10: Offline | N10: Returning | O10: Low | P10: Low | Q10: 45988 | R10: =IF(AND(K10>=100000,O10="High"),"Premium Customer",IF(AND(I10>=12,K10>=50000),"Loyal Customer",IF(AND(P10="High",J10<1500),"Bargain Seeker",IF(AND(TODAY()-Q10>180,I10<5),"At Risk","General Customer")))) -> General Customer
A11: CUST0008 | B11: 53 | C11: Female | D11: Kolkata | E11: East | F11: High | G11: 65014 | H11: Business Owner | I11: 22 | J11: 7112.87 | K11: 156483.14 | L11: Books | M11: Online | N11: New | O11: High | P11: High | Q11: 45640 | R11: =IF(AND(K11>=100000,O11="High"),"Premium Customer",IF(AND(I11>=12,K11>=50000),"Loyal Customer",IF(AND(P11="High",J11<1500),"Bargain Seeker",IF(AND(TODAY()-Q11>180,I11<5),"At Risk","General Customer")))) -> Premium Customer
A12: CUST0009 | B12: 29 | C12: Other | D12: Ahmedabad | E12: West | F12: Low | G12: 18317 | H12: Self-Employed | I12: 21 | J12: 4209 | K12: 88389 | L12: Electronics | M12: Offline | N12: Returning | O12: Low | P12: Medium | Q12: 45457 | R12: =IF(AND(K12>=100000,O12="High"),"Premium Customer",IF(AND(I12>=12,K12>=50000),"Loyal Customer",IF(AND(P12="High",J12<1500),"Bargain Seeker",IF(AND(TODAY()-Q12>180,I12<5),"At Risk","General Customer")))) -> Loyal Customer
A13: CUST0010 | B13: 37 | C13: Female | D13: Ahmedabad | E13: West | F13: Low | G13: 13923 | H13: Student | I13: 19 | J13: 7591.51 | K13: 144238.69 | L13: Grocery | M13: Online | N13: Returning | O13: Low | P13: Medium | Q13: 45362 | R13: =IF(AND(K13>=100000,O13="High"),"Premium Customer",IF(AND(I13>=12,K13>=50000),"Loyal Customer",IF(AND(P13="High",J13<1500),"Bargain Seeker",IF(AND(TODAY()-Q13>180,I13<5),"At Risk","General Customer")))) -> Loyal Customer
A14: CUST0011 | B14: 56 | C14: Male | D14: Ahmedabad | E14: West | F14: High | G14: 76365 | H14: Salaried | I14: 23 | J14: 2700.22 | K14: 62105.06 | L14: Travel | M14: Online | N14: Returning | O14: High | P14: Medium | Q14: 45740 | R14: =IF(AND(K14>=100000,O14="High"),"Premium Customer",IF(AND(I14>=12,K14>=50000),"Loyal Customer",IF(AND(P14="High",J14<1500),"Bargain Seeker",IF(AND(TODAY()-Q14>180,I14<5),"At Risk","General Customer")))) -> Loyal Customer
A15: CUST0012 | B15: 55 | C15: Male | D15: Hyderabad | E15: South | F15: Low | G15: 19075 | H15: Student | I15: 1 | J15: 846.65 | K15: 846.65 | L15: Fashion | M15: Online | N15: Returning | O15: Medium | P15: Low | Q15: 45324 | R15: =IF(AND(K15>=100000,O15="High"),"Premium Customer",IF(AND(I15>=12,K15>=50000),"Loyal Customer",IF(AND(P15="High",J15<1500),"Bargain Seeker",IF(AND(TODAY()-Q15>180,I15<5),"At Risk","General Customer")))) -> At Risk
... A123: CUST0120 | B123: 58 | C123: Male | D123: Hyderabad | E123: South | F123: High | G123: 119924 | H123: Freelancer | I123: 3 | J123: 4169.81 | K123: 12509.43 | L123: Beauty | M123: Online | N123: New | O123: Low | P123: High | Q123: 45449 | R123: =IF(AND(K123>=100000,O123="High"),"Premium Customer",IF(AND(I123>=12,K123>=50000),"Loyal Customer",IF(AND(P123="High",J123<1500),"Bargain Seeker",IF(AND(TODAY()-Q123>180,I123<5),"At Risk","General Customer")))) -> At Risk

Sheet KPI Summary
A1: 📈 KPI Summary | Market Research & Customer Segmentation Tool | FY 2024-25
A3: 👥 | D3: 💰 | G3: 🛒 | J3: ⭐
A4: =COUNTA('Raw Data'!A4:A123) -> 120 | D4: =SUM('Raw Data'!K4:K123) -> 7049663.5 | G4: =AVERAGE('Raw Data'!J4:J123) -> 4092.6306 | J4: =COUNTIFS('Raw Data'!R4:R123,"Premium Customer") -> 5
A5: Total Customers | D5: Total Revenue (₹) | G5: Avg Order Value (₹) | J5: Premium Customers
A8: ❤️ | D8: ⚠️ | G8: 🏷️ | J8: 🔄
A9: =COUNTIFS('Raw Data'!R4:R123,"Loyal Customer") -> 51 | D9: =COUNTIFS('Raw Data'!R4:R123,"At Risk") -> 13 | G9: =COUNTIFS('Raw Data'!R4:R123,"Bargain Seeker") -> 5 | J9: =COUNTIFS('Raw Data'!N4:N123,"Returning")/COUNTA('Raw Data'!A4:A123) -> 0.675
A10: Loyal Customers | D10: At Risk Customers | G10: Bargain Seekers | J10: Repeat Customer %
A13: 📊 | D13: 🌐 | G13: 🔥 | J13: 🏆
A14: =AVERAGE('Raw Data'!I4:I123) -> 13.716667 | D14: =COUNTIFS('Raw Data'!M4:M123,"Online")/COUNTA('Raw Data'!A4:A123) -> 0.525 | G14: =COUNTIFS('Raw Data'!O4:O123,"High")/COUNTA('Raw Data'!A4:A123) -> 0.38333333 | J14: =SUMIFS('Raw Data'!K4:K123,'Raw Data'!R4:R123,"Premium Customer") -> 696035.32
A15: Avg Purchase Freq | D15: Online Channel % | G15: High Engagement % | J15: Top Segment Revenue
A18: SEGMENT-WISE PERFORMANCE ANALYSIS
A19: Customer Segment | B19: Count | C19: % of Total | D19: Total Revenue (₹) | E19: Avg Order Value (₹) | F19: Avg Purchase Freq | G19: Avg Annual Income (₹) | H19: High Engagement % | I19: Online Channel % | J19: Repeat Customer % | K19: Revenue Share % | L19: Recommendation
A20: Premium Customer | B20: =COUNTIFS('Raw Data'!R4:R123,"Premium Customer") -> 5 | C20: =COUNTIFS('Raw Data'!R4:R123,"Premium Customer")/COUNTA('Raw Data'!A4:A123) -> 0.041666667 | D20: =SUMIFS('Raw Data'!K4:K123,'Raw Data'!R4:R123,"Premium Customer") -> 696035.32 | E20: =IFERROR(AVERAGEIFS('Raw Data'!J4:J123,'Raw Data'!R4:R123,"Premium Customer"),0) -> 6935.748 | F20: =IFERROR(AVERAGEIFS('Raw Data'!I4:I123,'Raw Data'!R4:R123,"Premium Customer"),0) -> 20.2 | G20: =IFERROR(AVERAGEIFS('Raw Data'!G4:G123,'Raw Data'!R4:R123,"Premium Customer"),0) -> 43548.2 | H20: =IFERROR(COUNTIFS('Raw Data'!R4:R123,"Premium Customer",'Raw Data'!O4:O123,"High")/COUNTIFS('Raw Data'!R4:R123,"Premium Customer"),0) -> 1 | I20: =IFERROR(COUNTIFS('Raw Data'!R4:R123,"Premium Customer",'Raw Data'!M4:M123,"Online")/COUNTIFS('Raw Data'!R4:R123,"Premium Customer"),0) -> 0.8 | J20: =IFERROR(COUNTIFS('Raw Data'!R4:R123,"Premium Customer",'Raw Data'!N4:N123,"Returning")/COUNTIFS('Raw Data'!R4:R123,"Premium Customer"),0) -> 0.8 | K20: =IFERROR(SUMIFS('Raw Data'!K4:K123,'Raw Data'!R4:R123,"Premium Customer")/SUM('Raw Data'!K4:K123),0) -> 0.098733127 | L20: 🏆 Exclusive VIP treatment
A21: Loyal Customer | B21: =COUNTIFS('Raw Data'!R4:R123,"Loyal Customer") -> 51 | C21: =COUNTIFS('Raw Data'!R4:R123,"Loyal Customer")/COUNTA('Raw Data'!A4:A123) -> 0.425 | D21: =SUMIFS('Raw Data'!K4:K123,'Raw Data'!R4:R123,"Loyal Customer") -> 4819813.7 | E21: =IFERROR(AVERAGEIFS('Raw Data'!J4:J123,'Raw Data'!R4:R123,"Loyal Customer"),0) -> 5141.6818 | F21: =IFERROR(AVERAGEIFS('Raw Data'!I4:I123,'Raw Data'!R4:R123,"Loyal Customer"),0) -> 18.843137 | G21: =IFERROR(AVERAGEIFS('Raw Data'!G4:G123,'Raw Data'!R4:R123,"Loyal Customer"),0) -> 46512.098 | H21: =IFERROR(COUNTIFS('Raw Data'!R4:R123,"Loyal Customer",'Raw Data'!O4:O123,"High")/COUNTIFS('Raw Data'!R4:R123,"Loyal Customer"),0) -> 0.23529412 | I21: =IFERROR(COUNTIFS('Raw Data'!R4:R123,"Loyal Customer",'Raw Data'!M4:M123,"Online")/COUNTIFS('Raw Data'!R4:R123,"Loyal Customer"),0) -> 0.50980392 | J21: =IFERROR(COUNTIFS('Raw Data'!R4:R123,"Loyal Customer",'Raw Data'!N4:N123,"Returning")/COUNTIFS('Raw Data'!R4:R123,"Loyal Customer"),0) -> 0.7254902 | K21: =IFERROR(SUMIFS('Raw Data'!K4:K123,'Raw Data'!R4:R123,"Loyal Customer")/SUM('Raw Data'!K4:K123),0) -> 0.68369416 | L21: ❤️ Reward & retain
A22: Bargain Seeker | B22: =COUNTIFS('Raw Data'!R4:R123,"Bargain Seeker") -> 5 | C22: =COUNTIFS('Raw Data'!R4:R123,"Bargain Seeker")/COUNTA('Raw Data'!A4:A123) -> 0.041666667 | D22: =SUMIFS('Raw Data'!K4:K123,'Raw Data'!R4:R123,"Bargain Seeker") -> 43674.76 | E22: =IFERROR(AVERAGEIFS('Raw Data'!J4:J123,'Raw Data'!R4:R123,"Bargain Seeker"),0) -> 708.568 | F22: =IFERROR(AVERAGEIFS('Raw Data'!I4:I123,'Raw Data'!R4:R123,"Bargain Seeker"),0) -> 11.2 | G22: =IFERROR(AVERAGEIFS('Raw Data'!G4:G123,'Raw Data'!R4:R123,"Bargain Seeker"),0) -> 33822.2 | H22: =IFERROR(COUNTIFS('Raw Data'!R4:R123,"Bargain Seeker",'Raw Data'!O4:O123,"High")/COUNTIFS('Raw Data'!R4:R123,"Bargain Seeker"),0) -> 0.4 | I22: =IFERROR(COUNTIFS('Raw Data'!R4:R123,"Bargain Seeker",'Raw Data'!M4:M123,"Online")/COUNTIFS('Raw Data'!R4:R123,"Bargain Seeker"),0) -> 0.8 | J22: =IFERROR(COUNTIFS('Raw Data'!R4:R123,"Bargain Seeker",'Raw Data'!N4:N123,"Returning")/COUNTIFS('Raw Data'!R4:R123,"Bargain Seeker"),0) -> 0.2 | K22: =IFERROR(SUMIFS('Raw Data'!K4:K123,'Raw Data'!R4:R123,"Bargain Seeker")/SUM('Raw Data'!K4:K123),0) -> 0.0061952972 | L22: 🏷️ Flash sales & bundles
A23: At Risk | B23: =COUNTIFS('Raw Data'!R4:R123,"At Risk") -> 13 | C23: =COUNTIFS('Raw Data'!R4:R123,"At Risk")/COUNTA('Raw Data'!A4:A123) -> 0.10833333 | D23: =SUMIFS('Raw Data'!K4:K123,'Raw Data'!R4:R123,"At Risk") -> 73530.25 | E23: =IFERROR(AVERAGEIFS('Raw Data'!J4:J123,'Raw Data'!R4:R123,"At Risk"),0) -> 2511.2954 | F23: =IFERROR(AVERAGEIFS('Raw Data'!I4:I123,'Raw Data'!R4:R123,"At Risk"),0) -> 2.3846154 | G23: =IFERROR(AVERAGEIFS('Raw Data'!G4:G123,'Raw Data'!R4:R123,"At Risk"),0) -> 36127.231 | H23: =IFERROR(COUNTIFS('Raw Data'!R4:R123,"At Risk",'Raw Data'!O4:O123,"High")/COUNTIFS('Raw Data'!R4:R123,"At Risk"),0) -> 0.46153846 | I23: =IFERROR(COUNTIFS('Raw Data'!R4:R123,"At Risk",'Raw Data'!M4:M123,"Online")/COUNTIFS('Raw Data'!R4:R123,"At Risk"),0) -> 0.61538462 | J23: =IFERROR(COUNTIFS('Raw Data'!R4:R123,"At Risk",'Raw Data'!N4:N123,"Returning")/COUNTIFS('Raw Data'!R4:R123,"At Risk"),0) -> 0.76923077 | K23: =IFERROR(SUMIFS('Raw Data'!K4:K123,'Raw Data'!R4:R123,"At Risk")/SUM('Raw Data'!K4:K123),0) -> 0.010430321 | L23: ⚠️ Win-back campaign
A24: General Customer | B24: =COUNTIFS('Raw Data'!R4:R123,"General Customer") -> 46 | C24: =COUNTIFS('Raw Data'!R4:R123,"General Customer")/COUNTA('Raw Data'!A4:A123) -> 0.38333333 | D24: =SUMIFS('Raw Data'!K4:K123,'Raw Data'!R4:R123,"General Customer") -> 1416609.4 | E24: =IFERROR(AVERAGEIFS('Raw Data'!J4:J123,'Raw Data'!R4:R123,"General Customer"),0) -> 3435.2496 | F24: =IFERROR(AVERAGEIFS('Raw Data'!I4:I123,'Raw Data'!R4:R123,"General Customer"),0) -> 10.804348 | G24: =IFERROR(AVERAGEIFS('Raw Data'!G4:G123,'Raw Data'!R4:R123,"General Customer"),0) -> 46833.87 | H24: =IFERROR(COUNTIFS('Raw Data'!R4:R123,"General Customer",'Raw Data'!O4:O123,"High")/COUNTIFS('Raw Data'!R4:R123,"General Customer"),0) -> 0.45652174 | I24: =IFERROR(COUNTIFS('Raw Data'!R4:R123,"General Customer",'Raw Data'!M4:M123,"Online")/COUNTIFS('Raw Data'!R4:R123,"General Customer"),0) -> 0.45652174 | J24: =IFERROR(COUNTIFS('Raw Data'!R4:R123,"General Customer",'Raw Data'!N4:N123,"Returning")/COUNTIFS('Raw Data'!R4:R123,"General Customer"),0) -> 0.63043478 | K24: =IFERROR(SUMIFS('Raw Data'!K4:K123,'Raw Data'!R4:R123,"General Customer")/SUM('Raw Data'!K4:K123),0) -> 0.2009471 | L24: 📬 Nurture & upsell
A27: REGION-WISE PERFORMANCE
A28: Region | B28: Customers | C28: Total Revenue (₹) | D28: Avg Order Value (₹) | E28: Premium Count | F28: Online % | G28: Satisfaction Proxy
A29: North | B29: =COUNTIFS('Raw Data'!E4:E123,"North") -> 39 | C29: =SUMIFS('Raw Data'!K4:K123,'Raw Data'!E4:E123,"North") -> 2386428.9 | D29: =IFERROR(AVERAGEIFS('Raw Data'!J4:J123,'Raw Data'!E4:E123,"North"),0) -> 4438.0731 | E29: =COUNTIFS('Raw Data'!E4:E123,"North",'Raw Data'!R4:R123,"Premium Customer") -> 0 | F29: =IFERROR(COUNTIFS('Raw Data'!E4:E123,"North",'Raw Data'!M4:M123,"Online")/COUNTIFS('Raw Data'!E4:E123,"North"),0) -> 0.38461538 | G29: =IFERROR(AVERAGEIFS('Raw Data'!I4:I123,'Raw Data'!E4:E123,"North"),0) -> 14.153846
A30: South | B30: =COUNTIFS('Raw Data'!E4:E123,"South") -> 32 | C30: =SUMIFS('Raw Data'!K4:K123,'Raw Data'!E4:E123,"South") -> 1781865.6 | D30: =IFERROR(AVERAGEIFS('Raw Data'!J4:J123,'Raw Data'!E4:E123,"South"),0) -> 3879.9809 | E30: =COUNTIFS('Raw Data'!E4:E123,"South",'Raw Data'!R4:R123,"Premium Customer") -> 0 | F30: =IFERROR(COUNTIFS('Raw Data'!E4:E123,"South",'Raw Data'!M4:M123,"Online")/COUNTIFS('Raw Data'!E4:E123,"South"),0) -> 0.46875 | G30: =IFERROR(AVERAGEIFS('Raw Data'!I4:I123,'Raw Data'!E4:E123,"South"),0) -> 12.875
A31: East | B31: =COUNTIFS('Raw Data'!E4:E123,"East") -> 11 | C31: =SUMIFS('Raw Data'!K4:K123,'Raw Data'!E4:E123,"East") -> 424058.26 | D31: =IFERROR(AVERAGEIFS('Raw Data'!J4:J123,'Raw Data'!E4:E123,"East"),0) -> 2729.9691 | E31: =COUNTIFS('Raw Data'!E4:E123,"East",'Raw Data'!R4:R123,"Premium Customer") -> 1 | F31: =IFERROR(COUNTIFS('Raw Data'!E4:E123,"East",'Raw Data'!M4:M123,"Online")/COUNTIFS('Raw Data'!E4:E123,"East"),0) -> 0.72727273 | G31: =IFERROR(AVERAGEIFS('Raw Data'!I4:I123,'Raw Data'!E4:E123,"East"),0) -> 10.909091
A32: West | B32: =COUNTIFS('Raw Data'!E4:E123,"West") -> 38 | C32: =SUMIFS('Raw Data'!K4:K123,'Raw Data'!E4:E123,"West") -> 2457310.7 | D32: =IFERROR(AVERAGEIFS('Raw Data'!J4:J123,'Raw Data'!E4:E123,"West"),0) -> 4311.6255 | E32: =COUNTIFS('Raw Data'!E4:E123,"West",'Raw Data'!R4:R123,"Premium Customer") -> 4 | F32: =IFERROR(COUNTIFS('Raw Data'!E4:E123,"West",'Raw Data'!M4:M123,"Online")/COUNTIFS('Raw Data'!E4:E123,"West"),0) -> 0.65789474 | G32: =IFERROR(AVERAGEIFS('Raw Data'!I4:I123,'Raw Data'!E4:E123,"West"),0) -> 14.789474

Sheet Dashboard
A1: 📊 MARKET RESEARCH & CUSTOMER SEGMENTATION DASHBOARD | FY 2024–25
A2: Interactive Analytics Tool | Marketing & Strategy Team | Customer Intelligence Division
A4: 👥 | D4: 💰 | G4: 🛒 | J4: ⭐ | M4: ⚠️ | P4: 🔄
A5: =COUNTA('Raw Data'!A4:A123) -> 120 | D5: =SUM('Raw Data'!K4:K123) -> 7049663.5 | G5: =AVERAGE('Raw Data'!J4:J123) -> 4092.6306 | J5: =COUNTIFS('Raw Data'!R4:R123,"Premium Customer") -> 5 | M5: =COUNTIFS('Raw Data'!R4:R123,"At Risk") -> 13 | P5: =COUNTIFS('Raw Data'!N4:N123,"Returning")/COUNTA('Raw Data'!A4:A123) -> 0.675
A7: TOTAL CUSTOMERS | D7: TOTAL REVENUE | G7: AVG ORDER VALUE | J7: PREMIUM CUSTOMERS | M7: AT RISK CUSTOMERS | P7: REPEAT CUSTOMER %
A47: 🔎 KEY BUSINESS INSIGHTS & RECOMMENDATIONS
A48: 💰 Revenue Driver | D48: Premium Customers (≥₹1L spend + High Engagement) generate the highest revenue per customer. Prioritize VIP programs & exclusive offers to retain this group.
A49: ⚠️ Retention Alert | D49: At Risk customers (>180 days inactive, <5 purchases) need immediate win-back campaigns with personalized discount offers or loyalty incentives.
A50: 🛒 Channel Strategy | D50: Online channel dominates among 25-34 age group. Invest in digital marketing, push notifications, and app-exclusive deals for this segment.
A51: 🏷️ Discount Approach | D51: Bargain Seekers respond best to flash sales & bundle deals. Avoid deep discounts on Premium segment — it devalues brand perception.
A52: 🌍 Regional Focus | D52: North & West regions contribute highest revenue. South region shows growth potential with high engagement but moderate spend — requires targeted campaigns.
A53: 📊 Product Insight | D53: Electronics & Fashion drive highest Average Order Value. Grocery shows highest purchase frequency. Cross-sell Electronics to Grocery repeat buyers.
A54: At Risk | B54: =COUNTIFS('Raw Data'!R4:R123,"At Risk") -> 13 | C54: =SUMIFS('Raw Data'!K4:K123,'Raw Data'!R4:R123,"At Risk") -> 73530.25 | E54: West | F54: =SUMIFS('Raw Data'!K4:K123,'Raw Data'!E4:E123,"West") -> 2457310.7 | G54: =COUNTIFS('Raw Data'!E4:E123,"West") -> 38 | I54: Home & Decor | J54: =COUNTIFS('Raw Data'!L4:L123,"Home & Decor") -> 19 | L54: At Risk | M54: =IFERROR(AVERAGEIFS('Raw Data'!I4:I123,'Raw Data'!R4:R123,"At Risk"),0) -> 2.3846154 | N54: =IFERROR(AVERAGEIFS('Raw Data'!J4:J123,'Raw Data'!R4:R123,"At Risk"),0) -> 2511.2954
A55: General Customer | B55: =COUNTIFS('Raw Data'!R4:R123,"General Customer") -> 46 | C55: =SUMIFS('Raw Data'!K4:K123,'Raw Data'!R4:R123,"General Customer") -> 1416609.4 | I55: Sports | J55: =COUNTIFS('Raw Data'!L4:L123,"Sports") -> 14 | L55: General Customer | M55: =IFERROR(AVERAGEIFS('Raw Data'!I4:I123,'Raw Data'!R4:R123,"General Customer"),0) -> 10.804348 | N55: =IFERROR(AVERAGEIFS('Raw Data'!J4:J123,'Raw Data'!R4:R123,"General Customer"),0) -> 3435.2496
I56: Beauty | J56: =COUNTIFS('Raw Data'!L4:L123,"Beauty") -> 19
I57: Books | J57: =COUNTIFS('Raw Data'!L4:L123,"Books") -> 8
I58: Travel | J58: =COUNTIFS('Raw Data'!L4:L123,"Travel") -> 10
